Workbook

Sheet Cover & Method
A1: S
A2: U.S. Economic & Inflation Model
A3: Bottom-up forecasts for nominal GDP, inflation, interest rates and unemployment
A5: Andrew Pasten | FRL 6950 | Model frozen July 31, 2026
A7: Purpose
A8: This model forecasts the US economy twelve months forward. It is the basis for every allocation in the ACCM
A9: portfolio. Each component is built from published data. Judgment calls sit in labelled blue cells, so any
A10: number in the report traces back to either a public data series or a stated assumption.
A12: Model Architecture
A13: Sheet | B13: Output | C13: Primary source
A14: Consumer Build | B14: Consumer spending growth; unemployment rate | C14: BLS labor force, employment and wage data; Census population
A15: Inflation Build | B15: Blended inflation forecast | C15: Atlanta Fed Wage Tracker; BLS average hourly earnings; commodity spot and futures
A16: AI Capex Build | B16: Bottom-up investment cross-check (not an input) | C16: SEC EDGAR XBRL - five hyperscalers
A17: Investment Build | B17: Business investment growth | C17: BEA gross private domestic investment, adjusted
A18: Government Build | B18: Government spending growth | C18: BEA government consumption and investment
A19: Net Trade Build | B19: Change in the trade deficit; sector weight | C19: BEA net exports, adjusted
A20: Interest Rate Build | B20: 10-year Treasury forecast | C20: Policy path and term premium decomposition
A21: BEA Source Data | B21: Quarterly source series with outlier adjustment | C21: FRED (fred.stlouisfed.org)
A22: Data Adjustments | B22: Documentation of the 2025 Q1 restatement | C22: BEA quarterly detail
A23: SUMMARY | B23: Headline forecasts | C23: All build sheets
A24: Period Alignment | B24: Reconciliation of forecast horizons | C24: FOMC SEP; Philadelphia Fed SPF
... A28: Benchmarking | B28: Validation against professional forecasters | C28: Philadelphia Fed SPF; FOMC SEP; Bloomberg; J.P. Morgan
A30: Conventions
A31: Cell colour | B31: Meaning
A32: Blue | B32: Hard input — a data point or a stated assumption
A33: Black | B33: Formula calculated on this sheet
A34: Green | B34: Link to another sheet in this model
A36: Methodological Notes
A37: Outliers. When one quarter is distorted by a one-off event, we restate that quarter in the source data and recompute growth from the
A38: restated series. We fix the data, not the output. The correction is then visible, applies to every calculation built on it, and a reader can
A39: undo it. See Data Adjustments.
A40: Triangulation. Investment is forecast two ways - top-down from the national accounts, bottom-up from company filings - and the two are
A41: compared.
A42: Interest rates. The ten-year is split into an expected policy path plus a term premium. A growth-based estimate is kept as a separate check.

Sheet Data
A1: Data Vintage
A2: Every input in this model with its source, its as-of date, and its retrieval date. Model frozen July 31, 2026.
A8: Inputs by vintage
A9: Input | B9: Source | C9: Series / reference | D9: As-of date | E9: Note
A10: Hyperscaler capital expenditure | B10: SEC EDGAR XBRL (data.sec.gov) | C10: Company-concept API, five CIKs | D10: FY2025 and Q1 2026 filings | E10: Accession numbers on the AI Capex Build sheet; retrieved July 30, 2026
A11: Term premium decomposition | B11: Federal Reserve Bank of New York | C11: Adrian-Crump-Moench model, daily series | D11: July 23, 2026
A12: Federal Reserve projections | B12: Federal Reserve Board | C12: Summary of Economic Projections, Table 1 | D12: June 17, 2026
A13: Commodity refresh (sensitivity only) | B13: CME, CBOT, COMEX, ICE via Yahoo Finance | C13: Front month and July 2027 contracts | D13: July 25, 2026
A14: Investment, government, net exports | B14: BEA National Income and Product Accounts via FRED | C14: GPDI, GCE, NETEXP — quarterly, SAAR | D14: Series through 2026 Q1
A15: Labor force, employment, wages | B15: BLS Current Population Survey; BLS average hourly earnings; Atlanta Fed Wage Tracker | C15: Annual 2025 basis | D15: 2025 annual
A16: Commodity basket (in the forecast) | B16: Exchange-listed futures | C16: Spot and twelve-month forward, eight commodities | D16: Model construction, June-July 2026
A17: Professional forecaster survey | B17: Federal Reserve Bank of Philadelphia | C17: Survey of Professional Forecasters | D17: Q2 2026 survey
A18: Economist consensus | B18: Bloomberg ECFC | C18: United States | D18: July 2026
A21: Related deliverables
A22: Deliverable | B22: Newest data it contains | C22: Note
A23: ACCM Final Portfolio Report | B23: July 6, 2026 | C23: Bloomberg WIRP rate path and ANR analyst consensus are the newest inputs. Portfolio inception June 1, 2026; June backtest through June 30, 2026.
A24: This economic model | B24: July 30, 2026 | C24: Carries data newer than the report.
A25: JPM equity research report | B25: May 29, 2026 (purchase) / June 24, 2026 (capital return) | C25: Purchase decision priced at the 29 May close; the June capital-return announcement is a subsequent event.

Sheet SUMMARY
A1: Forecast Summary
A2: Twelve-month forward outlook. Every figure is calculated from the build sheets in this workbook.
A4: Nominal GDP Build
A5: GDP component | B5: Weight | C5: Growth forecast | D5: Contribution | E5: Basis
A6: Consumer spending | B6: 0.68 | C6: ='Consumer Build'!B31 -> 0.049308072 | D6: =B6*C6 -> 0.033529489 | E6: Labor force, wage growth and the saving rate
A7: Business investment | B7: 0.18 | C7: ='Investment Build'!B15 -> 0.043588622 | D7: =B7*C7 -> 0.0078459519 | E7: BEA investment data reconciled with a bottom-up capital expenditure build
A8: Government spending | B8: 0.17 | C8: ='Government Build'!B15 -> 0.044492146 | D8: =B8*C8 -> 0.0075636648 | E8: BEA government consumption and investment
A9: Net trade | B9: -0.03 | C9: ='Net Trade Build'!B8 -> -0.11632099 | D9: =B9*C9 -> 0.0034896298 | E9: BEA net exports; weight from the ten-year average share of GDP
A10: NOMINAL GDP GROWTH | B10: =SUM(B6:B9) -> 1 | D10: =SUM(D6:D9) -> 0.052428735
A12: Real Growth and Inflation
A13: Measure | B13: Value | C13: Derivation
A14: Nominal GDP growth | B14: =D10 -> 0.052428735
A15: Inflation forecast | B15: ='Inflation Build'!D29 -> 0.034285795 | C15: Blended labor and materials forecast
A16: REAL GDP GROWTH | B16: =(1+B14)/(1+B15)-1 -> 0.017541516 | C16: Nominal growth deflated by the inflation build. This is an approximation, not a GDP deflator. See note below.
A19: Interest Rates and Labor Market
A20: Measure | B20: Value | C20: Derivation
A21: TEN-YEAR TREASURY FORECAST | B21: ='Interest Rate Build'!B33 -> 0.049 | C21: Market-implied policy path plus a forecast term premium
A22: Growth-anchor cross-check | B22: ='Interest Rate Build'!B54 -> 0.041827311 | C22: Independent estimate; see Interest Rate Build
A23: UNEMPLOYMENT RATE | B23: ='Consumer Build'!B41 -> 0.043939485
A25: How to read this. Nominal GDP drives portfolio cash flows - revenues, interest and dividends are all nominal.
A26: Real GDP is the figure quoted in the press and the one to compare against published forecasts.
A27: The rate forecast sets fixed income positioning and the equity discount rate.
A28: Note on real GDP. The figure above deflates nominal growth by this model's inflation build, which is constructed from labor and materials costs on a CPI-style basis.
A29: The official real GDP series uses the GDP deflator, which excludes imports and weights components differently, and typically runs a few tenths below CPI.
A30: Real growth here is therefore best read as approximately 1.8 to 2.2 percent rather than as a point estimate.
A31: The portfolio rests on nominal growth, inflation and interest rates, each of which this model forecasts directly.

Sheet Consumer Build
A1: Consumer Build
A2: Consumer spending is forecast from its physical drivers: how many people work, what they earn, and how much of it they save.
A4: Step 1 — Labor Force Capacity
A5: Item | B5: Value | C5: Source / derivation
A6: 2025 labor force | B6: 170807000 | C6: BLS Current Population Survey
A7: 2025 employment | B7: 163493000 | C7: BLS Current Population Survey
A8: Working-age population (15-64) | B8: 273653000 | C8: Census / BLS
A9: Working-age population growth, ten-year CAGR | B9: =(283863000/268571000)^(1/10)-1 -> 0.0055530027 | C9: Compound growth of the 15-64 cohort over the prior decade
A10: Working-age population increase | B10: =B9*B8 -> 1519595.9 | C10: Demographic contribution to labor supply
A11: Net immigration | B11: 0 | C11: Set to zero: already embedded in the BLS population series used above
A12: Participation rate assumption | B12: 0.6238 | C12: ASSUMPTION: edges down from 62.42% in 2025. Applied to the full projected population.
A13: 2026 labor force at that participation | B13: =B12*(B8+B10+B11) -> 1.7165267e+08
A14: Net change in labor force | B14: =B13-B6 -> 845665.29 | C14: Demographics plus immigration plus participation
A15: 2026 labor force | B15: =B13 -> 1.7165267e+08
A18: Step 2 — Employment Forecast
A19: Item | B19: Value | C19: Source / derivation
A20: Upper limit: all new entrants employed | B20: =B14 -> 845665.29 | C20: Ceiling case in which labor force growth is fully absorbed
A21: Absorption rate | B21: 0.73 | C21: ASSUMPTION: 73% of new entrants find work, leaving unemployment drifting modestly higher
A22: Jobs added | B22: =B20*B21 -> 617335.66
A23: Employment growth rate | B23: =B22/B7 -> 0.003775915 | C23: Jobs added as a share of 2025 employment
A25: Step 3 — Income and Spending
A26: Item | B26: Value | C26: Source / derivation
A27: Wage growth | B27: ='Inflation Build'!B8 -> 0.035 | C27: Link: Inflation Build, labor component
A28: Employment growth | B28: =B23 -> 0.003775915
A29: Consumer income growth | B29: =(1+B28)*(1+B27)-1 -> 0.038908072 | C29: More workers multiplied by higher pay
A30: Change in the saving rate | B30: =AVERAGE(0.045,0.038,0.035,0.03,0.03)-0.046 -> -0.0104 | C30: Forecast average saving rate less the current rate; a falling rate releases income into spending
A31: CONSUMER SPENDING GROWTH | B31: =B29-B30 -> 0.049308072 | C31: Income growth plus the saving-rate drawdown
A33: Spending grows faster than income when households save less of what they earn. The exact identity divides the drawdown
A34: by one minus the saving rate, which would add slightly more. The simple addition used here is a little conservative.
A36: Step 4 — Unemployment Rate
A37: Item | B37: Value | C37: Source / derivation
A38: 2026 labor force | B38: =B15 -> 1.7165267e+08
A39: 2026 employment | B39: =B7+B22 -> 1.6411034e+08 | C39: 2025 employment plus jobs added
A40: 2026 unemployed | B40: =B38-B39 -> 7542329.6
A41: UNEMPLOYMENT RATE | B41: =B40/B38 -> 0.043939485

Sheet Inflation Build
A1: Inflation Build
A2: Cost-push framework: the price level is forecast from what producers pay for labor and for materials.
A4: Component 1 — Labor Costs
A5: Source | B5: Rate | C5: Notes
A6: Atlanta Fed Wage Growth Tracker | B6: 0.036 | C6: Median twelve-month wage growth of matched individuals
A7: BLS average hourly earnings, year over year | B7: 0.034 | C7: Establishment survey, total private
A8: Average wage growth | B8: =AVERAGE(B6:B7) -> 0.035 | C8: Feeds this sheet and the Consumer Build
A10: Component 2 — Materials Basket
A11: Commodity | B11: Weight | C11: Spot | D11: One-year futures | E11: Implied change | F11: Weighted
A12: WTI crude oil | B12: 0.3 | C12: 68.78 | D12: 67.92 | E12: =(D12/C12)^0.5-1 -> -0.0062714831 | F12: =E12*B12 -> -0.0018814449
A13: Soybeans | B13: 0.1 | C13: 1122.75 | D13: 1175.75 | E13: =D13/C13-1 -> 0.047205522 | F13: =E13*B13 -> 0.0047205522
A14: Corn | B14: 0.1 | C14: 417.5 | D14: 494.25 | E14: =D14/C14-1 -> 0.18383234 | F14: =E14*B14 -> 0.018383234
A15: Copper | B15: 0.15 | C15: 6.2275 | D15: 6.4665 | E15: =D15/C15-1 -> 0.038378161 | F15: =E15*B15 -> 0.0057567242
A16: Gold | B16: 0.2 | C16: 4110.2 | D16: 4265 | E16: =D16/C16-1 -> 0.037662401 | F16: =E16*B16 -> 0.0075324802
A17: Sugar | B17: 0.05 | C17: 13.92 | D17: 15.07 | E17: =D17/C17-1 -> 0.082614943 | F17: =E17*B17 -> 0.0041307471
A18: Coffee | B18: 0.05 | C18: 2.484 | D18: 2.3545 | E18: =D18/C18-1 -> -0.052133655 | F18: =E18*B18 -> -0.0026066828
A19: Live cattle | B19: 0.05 | C19: 241.775 | D19: 225.975 | E19: =D19/C19-1 -> -0.065350016 | F19: =E19*B19 -> -0.0032675008
A20: Total weight / net materials inflation | B20: =SUM(B12:B19) -> 1 | F20: =SUM(F12:F19) -> 0.032768109
A21: Each commodity's one-year futures price against spot is the market's implied price change over the forecast
A22: year, so this is forward-looking rather than historical. WTI uses the square root of the ratio to dampen a
A23: single volatile energy quote. Weights approximate each input's share of production costs across the economy.
A25: Blended Forecast
A26: Component | B26: Weight | C26: Rate | D26: Weighted contribution
A27: Labor | B27: 0.68 | C27: =$B$8 -> 0.035 | D27: =B27*C27 -> 0.0238
A28: Materials | B28: 0.32 | C28: =$F$20 -> 0.032768109 | D28: =B28*C28 -> 0.010485795
A29: INFLATION FORECAST | B29: =SUM(B27:B28) -> 1 | D29: =SUM(D27:D28) -> 0.034285795

Sheet BEA Source Data
A1: BEA Source Data
A2: U.S. Bureau of Economic Analysis, National Income and Product Accounts, via FRED. Nominal, seasonally adjusted annual rates, $ billions.
A4: Quarter | B4: GPDI reported | C4: GCE reported | D4: NETEXP reported | E4: GPDI adjusted | F4: GCE adjusted | G4: NETEXP adjusted
A5: 2015 Q1 | B5: 3282.283 | C5: 3187.915 | D5: -526.432 | E5: =B5 -> 3282.283 | F5: =C5 -> 3187.915 | G5: =D5 -> -526.432
A6: 2015 Q2 | B6: 3291.104 | C6: 3234.067 | D6: -509.527 | E6: =B6 -> 3291.104 | F6: =C6 -> 3234.067 | G6: =D6 -> -509.527
A7: 2015 Q3 | B7: 3303.66 | C7: 3253.554 | D7: -538.082 | E7: =B7 -> 3303.66 | F7: =C7 -> 3253.554 | G7: =D7 -> -538.082
A8: 2015 Q4 | B8: 3276.879 | C8: 3258.142 | D8: -523.238 | E8: =B8 -> 3276.879 | F8: =C8 -> 3258.142 | G8: =D8 -> -523.238
A9: 2016 Q1 | B9: 3244.317 | C9: 3270.141 | D9: -511.682 | E9: =B9 -> 3244.317 | F9: =C9 -> 3270.141 | G9: =D9 -> -511.682
A10: 2016 Q2 | B10: 3246.381 | C10: 3289.566 | D10: -489.37 | E10: =B10 -> 3246.381 | F10: =C10 -> 3289.566 | G10: =D10 -> -489.37
A11: 2016 Q3 | B11: 3261.571 | C11: 3315.171 | D11: -481.229 | E11: =B11 -> 3261.571 | F11: =C11 -> 3315.171 | G11: =D11 -> -481.229
A12: 2016 Q4 | B12: 3360.952 | C12: 3337.245 | D12: -530.806 | E12: =B12 -> 3360.952 | F12: =C12 -> 3337.245 | G12: =D12 -> -530.806
A13: 2017 Q1 | B13: 3363.101 | C13: 3353.096 | D13: -533.42 | E13: =B13 -> 3363.101 | F13: =C13 -> 3353.096 | G13: =D13 -> -533.42
A14: 2017 Q2 | B14: 3432.968 | C14: 3370.444 | D14: -553.499 | E14: =B14 -> 3432.968 | F14: =C14 -> 3370.444 | G14: =D14 -> -553.499
A15: 2017 Q3 | B15: 3500.142 | C15: 3398.886 | D15: -531.498 | E15: =B15 -> 3500.142 | F15: =C15 -> 3398.886 | G15: =D15 -> -531.498
A16: 2017 Q4 | B16: 3574.446 | C16: 3466.137 | D16: -554.897 | E16: =B16 -> 3574.446 | F16: =C16 -> 3466.137 | G16: =D16 -> -554.897
... A44: 2024 Q4 | B44: 5261.83 | C44: 5150.725 | D44: -938.666 | E44: =B44 -> 5261.83 | F44: =C44 -> 5150.725 | G44: =D44 -> -938.666
A45: 2025 Q1 | B45: 5556.216 | C45: 5195.517 | D45: -1264.604 | E45: =AVERAGE(B44,B46) -> 5310.231 | F45: =C45 -> 5195.517 | G45: =AVERAGE(D44,D46) -> -919.2325
A46: 2025 Q2 | B46: 5358.632 | C46: 5236.97 | D46: -899.799 | E46: =B46 -> 5358.632 | F46: =C46 -> 5236.97 | G46: =D46 -> -899.799
A47: 2025 Q3 | B47: 5419.029 | C47: 5324.402 | D47: -756.57 | E47: =B47 -> 5419.029 | F47: =C47 -> 5324.402 | G47: =D47 -> -756.57
A48: 2025 Q4 | B48: 5500.636 | C48: 5343.513 | D48: -784.975 | E48: =B48 -> 5500.636 | F48: =C48 -> 5343.513 | G48: =D48 -> -784.975
A49: 2026 Q1 | B49: 5634.016 | C49: 5416.715 | D49: -819.956 | E49: =B49 -> 5634.016 | F49: =C49 -> 5416.715 | G49: =D49 -> -819.956
A51: Series: GPDI, GCE, NETEXP. Source: fred.stlouisfed.org (BEA 'Gross Domestic Product' release, last updated June 25, 2026).
A52: The adjusted columns restate 2025 Q1 to the average of the quarters either side, removing the tariff pull-forward. All other
A53: quarters are unchanged. Every forecast here uses the adjusted columns. See Data Adjustments.

Sheet Data Adjustments
A1: Data Adjustments
A2: Documentation of the single outlier restatement applied to the source data.
A4: What happened. Ahead of 2025 tariffs, importers bought and stockpiled foreign goods. One such purchase is recorded twice
A5: in the national accounts: imports rise, which cuts net exports and subtracts from GDP; inventories rise, which lifts
A6: investment and adds to GDP. The two largely cancel in total GDP but push the component growth rates in opposite
A7: directions, because 2025 Q1 sits inside the comparison window of every measure built from it.
A9: Evidence — the offsetting quarters
A10: Quarter over quarter | B10: Investment | C10: Net exports | D10: Combined effect on GDP
A11: 2024 Q4 to 2025 Q1 — stockpiling | B11: 294.4 | C11: -325.9 | D11: -31.5
A12: 2025 Q1 to 2025 Q2 — unwind | B12: -197.6 | C12: 364.8 | D12: 167.2
A13: $ billions, seasonally adjusted annual rate. The near-cancellation in the combined column is the signature of one transaction booked on both sides of the accounts.
A15: Restatement applied
A16: Series | B16: 2025 Q1 as reported | C16: 2025 Q1 restated | D16: Basis
A17: GPDI — investment | B17: ='BEA Source Data'!B45 -> 5556.216 | C17: ='BEA Source Data'!E45 -> 5310.231 | D17: Average of 2024 Q4 and 2025 Q2 — linear interpolation across the distorted quarter
A18: NETEXP — net exports | B18: ='BEA Source Data'!D45 -> -1264.604 | C18: ='BEA Source Data'!G45 -> -919.2325 | D18: Average of 2024 Q4 and 2025 Q2 — linear interpolation across the distorted quarter
A20: Method. Linear interpolation across a single distorted observation is the standard fix for an identified one-
A21: off outlier, and is what statistical agencies' own seasonal adjustment software does when it detects one. We
A22: apply it to the data, not to the forecast, so the correction is visible, applies to every measure built from
A23: the series, and can be removed by anyone who disagrees. Government spending needed no adjustment: its trailing
A24: and current growth rates agree closely, which is itself evidence the series was undistorted.
A26: Effect on the derived measures
A27: Measure | B27: From reported data | C27: From adjusted data
A28: Investment, trailing-year growth | B28: 3.79% | C28: 2.62%
A29: Investment, latest year over year | B29: 1.40% | C29: 6.10%
A30: Investment, blended base | B30: 2.59% | C30: 4.36%
A31: Net trade, change in deficit | B31: -19.2% | C31: -11.6%
A33: The reported spike inflates the trailing measure, which has it in the numerator, and deflates the year-over-year measure, which has it in the denominator. The
A34: second effect is larger, so removing the distortion raises the investment forecast and reduces the apparent narrowing of the trade deficit.

Sheet Investment Build
A1: Investment Build
A2: Business investment: BEA gross private domestic investment — equipment, structures, intellectual property and inventories.
A4: Growth Measurement (from adjusted source data)
A5: Measure | B5: Value | C5: Source / derivation
A6: Trailing-year growth (2025 average versus 2024 average) | B6: =AVERAGE('BEA Source Data'!E45:E48)/AVERAGE('BEA Source Data'!E41:E44)-1 -> 0.026203436 | C6: Four quarters against the prior four
A7: Latest year over year (2026 Q1 versus 2025 Q1) | B7: ='BEA Source Data'!E49/'BEA Source Data'!E45-1 -> 0.060973807 | C7: Newest quarter against the same quarter a year earlier
A8: Latest quarter, annualised | B8: =('BEA Source Data'!E49/'BEA Source Data'!E48)^4-1 -> 0.10057762 | C8: Reference only — single-quarter readings are volatile
A10: Forecast Construction
A11: Item | B11: Value | C11: Source / derivation
A12: Weight on the trailing-year measure | B12: 0.5 | C12: ASSUMPTION: equal weight between the stable and the current measure
A13: Top-down base forecast | B13: =B6*B12+B7*(1-B12) -> 0.043588622 | C13: Weighted blend of the two measures above
A14: Memo — bottom-up cross-check | B14: ='AI Capex Build'!B44 -> 0.047627881 | C14: Independent build from audited capital expenditure in SEC filings. Not averaged into the forecast; see note below.
A15: FORECAST | B15: =B13 -> 0.043588622 | C15: The national accounts measure is the forecast. The bottom-up build validates it.
A17: The forecast is the top-down measure from the national accounts, using the adjusted series so the 2025 Q1 distortion does not suppress the year-over-year reading. That is the standard basis
A18: for forecasting national investment.
A19: The bottom-up build from five hyperscalers' filings is a cross-check, shown above as a memo only. It is deliberately not averaged in. Their US-deployed capital expenditure is about 5.1% of private investment, too small a sample to infer the whole.
A20: a sample to infer the whole. Their value is confirmatory.
A21: The two methods use entirely separate data - government statistics against company filings - so agreement between them is real evidence, not an artifact. No judgment overlay is applied here.

Sheet AI Capex Build
A1: AI Capital Expenditure — Bottom-Up Cross-Check
A2: Checks the top-down investment forecast against audited capex from SEC filings. Not an input to the forecast.
A4: Purpose. Analysts covering semiconductors, networking, electrical equipment, data-center REITs and power utilities routinely add up hyperscaler capex to size demand. That use is standard.
A5: Forecasting national investment from it is not. National investment is built from Census shipments and orders, construction spending and capital-goods surveys. These five companies are under
A6: 5.1% of private investment once their own 65% US share is applied.
A7: So this build does two jobs: it cross-checks the national accounts figure, and it is the evidence behind the Industrials and Energy overweights. It is not a co-equal input to GDP.
A9: Step 1 — Capital expenditure as filed (US$ billions)
A10: Company | B10: CIK | C10: CY2024 | D10: CY2025 | E10: y/y | F10: Q1 2025 | G10: Q1 2026 | H10: y/y | I10: Source: latest annual report
A11: Amazon | B11: 1018724 | C11: 82.999 | D11: 131.819 | E11: =D11/C11-1 -> 0.58819986 | F11: 25.019 | G11: 44.203 | H11: =G11/F11-1 -> 0.76677725 | I11: 10-K filed 06 Feb 2026 — accn 0001018724-26-000004
A12: Microsoft | B12: 789019 | C12: 55.552 | D12: 83.094 | E12: =D12/C12-1 -> 0.49578773 | F12: 16.745 | G12: 30.876 | H12: =G12/F12-1 -> 0.8438937 | I12: 10-K filed 30 Jul 2025 — accn 0000950170-25-100235
A13: Alphabet | B13: 1652044 | C13: 52.535 | D13: 91.447 | E13: =D13/C13-1 -> 0.74068716 | F13: 17.197 | G13: 35.674 | H13: =G13/F13-1 -> 1.0744316 | I13: 10-K filed 05 Feb 2026 — accn 0001652044-26-000018
A14: Meta | B14: 1326801 | C14: 37.256 | D14: 69.691 | E14: =D14/C14-1 -> 0.87059802 | F14: 12.941 | G14: 18.997 | H14: =G14/F14-1 -> 0.46797002 | I14: 10-K filed 29 Jan 2026 — accn 0001628280-26-003942
A15: Oracle | B15: 1341439 | C15: 14.933 | D15: 48.25 | E15: =D15/C15-1 -> 2.2310989 | F15: 5.862 | G15: 18.635 | H15: =G15/F15-1 -> 2.1789492 | I15: 10-K filed 18 Jun 2025 — accn 0000950170-25-087926
A16: TOTAL | C16: =SUM(C11:C15) -> 243.275 | D16: =SUM(D11:D15) -> 424.301 | E16: =D16/C16-1 -> 0.74412085 | F16: =SUM(F11:F15) -> 77.764 | G16: =SUM(G11:G15) -> 148.385 | H16: =G16/F16-1 -> 0.90814516
A17: All figures are the cash flow line 'purchases of property and equipment', retrieved July 30, 2026 from the SEC XBRL API (data.sec.gov). Tag: PaymentsToAcquirePropertyPlantAndEquipment for Microsoft, Alphabet, Meta and Oracle; PaymentsToAcquireProductiveAssets for Amazon.
A18: Three comparability caveats, disclosed rather than adjusted away:
A19: (i) Amazon's tag also picks up software and intangibles, so its figure is slightly broader.
A20: (ii) Microsoft's fiscal year ends 30 June and Oracle's 31 May, so their calendar figures are rebuilt from quarterly filings. Oracle's quarters do not line up with calendar quarters at all, so its CY2025 is a March-to-February proxy.
A21: (iii) Equipment acquired under finance leases is excluded, so true capital spending is higher - materially so for Amazon.
A23: Step 2 — Forward scenarios
A24: Scenario | B24: 2026 capex ($B) | C24: Basis
A25: Floor — latest quarter annualised | B25: =G16*4 -> 593.54 | C25: Q1 2026 run rate held flat. Conservative: capital expenditure has ramped within each recent year.
A26: Ceiling — latest year-over-year rate sustained | B26: =D16*(1+H16) -> 809.6279 | C26: CY2025 grown at the Q1 2026 year-over-year rate. Aggressive: assumes 90% growth persists a full year.
A27: ADOPTED — midpoint | B27: =AVERAGE(B25,B26) -> 701.58395 | C27: Neither extreme is defensible on its own; the midpoint is carried forward.
A28: Implied growth on the adopted scenario | B28: =B27/D16-1 -> 0.65350529
A29: Forward capex guidance is given on earnings calls, not in XBRL, and is a company statement rather than an
A30: audited figure. Both scenarios above come from filed data only, which keeps the whole build traceable to
A31: primary sources. The adopted midpoint falls inside the range of published sell-side estimates for these five.
A34: Step 3 — Mapping to U.S. private investment
A35: Item | B35: Value | C35: Source / derivation
A36: Incremental capital expenditure, 2026 versus 2025 ($B) | B36: =B27-D16 -> 277.28295
A37: Share located in the United States | B37: 0.65 | C37: ASSUMPTION — see Limitations. Hyperscalers build globally; this share is not disclosed in a directly usable form.
A38: Incremental U.S. investment ($B) | B38: =B36*B37 -> 180.23392
A39: 2025 gross private domestic investment ($B) | B39: =AVERAGE('BEA Source Data'!E45:E48) -> 5397.132 | C39: Adjusted four-quarter average
A40: Hyperscaler share of total private investment | B40: =D16/B39 -> 0.078616013 | C40: Five companies as a share of all U.S. private investment
A41: AI contribution to investment growth | B41: =B38/B39 -> 0.033394387
A42: Non-AI investment growth | B42: 0.015 | C42: ASSUMPTION: rate-sensitive equipment, structures and housing grow slowly with the ten-year near 4.5%
A43: Non-AI contribution | B43: =(B39-D16*B37)*B42/B39 -> 0.014233494
A44: BOTTOM-UP INVESTMENT GROWTH | B44: =B41+B43 -> 0.047627881 | C44: Carried to the Investment Build as a memorandum cross-check only
A46: Imported equipment is not deducted here. A server installed in a US data center is US private investment and counts in full within
...

Sheet Government Build
A1: Government Build
A2: Government spending: BEA government consumption expenditures and gross investment, federal plus state and local.
A4: Growth Measurement (from adjusted source data)
A5: Measure | B5: Value | C5: Source / derivation
A6: Trailing-year growth (2025 average versus 2024 average) | B6: =AVERAGE('BEA Source Data'!F45:F48)/AVERAGE('BEA Source Data'!F41:F44)-1 -> 0.04640951 | C6: Four quarters against the prior four
A7: Latest year over year (2026 Q1 versus 2025 Q1) | B7: ='BEA Source Data'!F49/'BEA Source Data'!F45-1 -> 0.042574781 | C7: Newest quarter against the same quarter a year earlier
A8: Latest quarter, annualised | B8: =('BEA Source Data'!F49/'BEA Source Data'!F48)^4-1 -> 0.055933242 | C8: Reference only — single-quarter readings are volatile
A10: Forecast Construction
A11: Item | B11: Value | C11: Source / derivation
A12: Weight on the trailing-year measure | B12: 0.5 | C12: ASSUMPTION: equal weight between the stable and the current measure
A13: Top-down base forecast | B13: =B6*B12+B7*(1-B12) -> 0.044492146 | C13: Weighted blend of the two measures above
A14: Judgment overlay | B14: 0 | C14: No overlay: the measured trend already reflects the current fiscal stance. Adjust from CBO baseline projections if the outlook changes.
A15: FORECAST | B15: =B13+B14 -> 0.044492146
A17: State and local government is roughly 60% of this series and tracks tax receipts, which makes the total stable
A18: and its recent trend a reasonable forecast. The trailing and current measures agree closely - unlike
A19: investment - which is itself evidence that no data adjustment is needed here. Cross-checks: CBO baseline
A20: outlay projections and the Treasury Monthly Statement.

Sheet Net Trade Build
A1: Net Trade Build
A2: Net exports: BEA net exports of goods and services. Measured in levels rather than growth rates, because the series is negative.
A4: Deficit Measurement (from adjusted source data)
A5: Measure | B5: Value | C5: Source / derivation
A6: Trailing twelve-month average net exports ($B) | B6: =AVERAGE('BEA Source Data'!G46:G49) -> -815.325 | C6: 2025 Q2 through 2026 Q1
A7: Prior twelve-month average net exports ($B) | B7: =AVERAGE('BEA Source Data'!G42:G45) -> -922.64838 | C7: 2024 Q2 through 2025 Q1, using the restated 2025 Q1
A8: FORECAST: change in net exports | B8: =B6/B7-1 -> -0.11632099 | C8: Negative indicates a narrowing deficit, which adds to GDP
A10: Why a negative figure adds to GDP. Output is consumption plus investment plus government plus exports less imports. Imports are
A11: subtracted because spending on foreign goods shows up in the other components but was not produced here. When the deficit narrows,
A12: less foreign production is subtracted and measured output rises. In the summary, a negative sector weight times a negative change
A13: gives a positive contribution. No judgment overlay: the distortion in this series was removed in the data.
A16: Sector Weight Derivation
A17: Year | B17: Nominal GDP ($B) | C17: Net exports ($B) | D17: Net exports as % of GDP
A18: 2015 | B18: 18295 | C18: 524.3 | D18: =C18/B18 -> 0.028658103
A19: 2016 | B19: 18804.9 | C19: -503.3 | D19: =C19/B19 -> -0.026764301
A20: 2017 | B20: 19612.1 | C20: -543.3 | D20: =C20/B20 -> -0.027702286
A21: 2018 | B21: 20656.5 | C21: -593.1 | D21: =C21/B21 -> -0.028712512
A22: 2019 | B22: 21540 | C22: -577.3 | D22: =C22/B22 -> -0.0268013
A23: 2020 | B23: 21375.3 | C23: -618.6 | D23: =C23/B23 -> -0.028939945
A24: 2021 | B24: 23725.6 | C24: -849.2 | D24: =C24/B24 -> -0.035792562
A25: 2022 | B25: 26054.6 | C25: -937.9 | D25: =C25/B25 -> -0.035997482
A26: 2023 | B26: 27811.5 | C26: -786.5 | D26: =C26/B26 -> -0.028279668
A27: 2024 | B27: 29298 | C27: -898.5 | D27: =C27/B27 -> -0.030667622
A28: 2025 | B28: 30779 | C28: -920.8 | D28: =C28/B28 -> -0.029916502
A29: Average, 2016-2025 | D29: =AVERAGE(D19:D28) -> -0.029957418
A31: The trade deficit has averaged close to -3% of GDP over the past decade. That is the basis for the -3% sector
A32: weight in the summary. The 2015 figure is a reporting anomaly and is left out of the average.

Sheet Interest Rate Build
A1: Interest Rate Build
A2: Ten-year Treasury forecast decomposed into an expected policy path and a term premium, anchored to published market and Federal Reserve data.
A4: Observed — Market Decomposition (Adrian-Crump-Moench model, Federal Reserve Bank of New York)
A5: Component | B5: Value | C5: Source
A6: Ten-year fitted yield | B6: 0.047765 | C6: ACM model, July 23, 2026 (newyorkfed.org)
A7: Risk-neutral yield — expected average policy rate | B7: 0.040569 | C7: ACM model, July 23, 2026. What the market expects the overnight rate to average over ten years.
A8: Term premium | B8: 0.007196 | C8: ACM model, July 23, 2026. Compensation demanded for holding duration.
A9: Check: components sum to the fitted yield | B9: =B7+B8 -> 0.047765 | C9: Identity: yield = expected policy path + term premium
A11: Observed — Federal Reserve Projections (Summary of Economic Projections, June 2026)
A12: Year | B12: Median federal funds rate | C12: Note
A13: 2026 | B13: 0.038 | C13: Raised from 3.4% in the March projection
A14: 2027 | B14: 0.036 | C14: Raised from 3.1%
A15: 2028 | B15: 0.034 | C15: Raised from 3.1%
A16: Longer run | B16: 0.031 | C16: The Committee estimate of the neutral rate
A17: Implied ten-year average of the FOMC path | B17: =(B13+B14+B15+B16*7)/10 -> 0.0325 | C17: Three projection years followed by seven years at the longer-run rate
A19: Analysis — the market disagrees with the Committee
A20: Measure | B20: Value | C20: Interpretation
A21: Market-implied average policy rate | B21: =B7 -> 0.040569
A22: FOMC-implied average policy rate | B22: =B17 -> 0.0325
A23: Gap | B23: =B21-B22 -> 0.008069 | C23: The market prices a higher path than the Committee projects, on the view that sticky inflation keeps the Fed from returning to neutral
A25: This gap is the most important observation in the model. The Committee projects easing toward a 3.1% neutral rate. The market
A26: prices an average overnight rate well above that. ACCM sides with the market, and the direction of travel supports it: the June
A27: 2026 projections raised the 2026 median from 3.4% to 3.8%, after projecting cuts in the two rounds before.
A29: ACCM Forecast
A30: Building block | B30: Value | C30: Basis
A31: Expected average policy rate | B31: 0.0405 | C31: ASSUMPTION: held at the market-implied level; inflation persistence keeps the near-term path elevated while the long-run anchor pulls it down
A32: Term premium | B32: 0.0085 | C32: ASSUMPTION: rises from the observed 0.72% on AI capital demand, Treasury supply and balance-sheet runoff; still well below the pre-2008 norm
A33: TEN-YEAR TREASURY FORECAST | B33: =B31+B32 -> 0.049
A34: Change from the observed yield | B34: =B33-B6 -> 0.001235 | C34: Modest increase from the prevailing level
A36: Term Premium Drivers
A37: Driver | B37: Direction | C37: Reasoning
A38: AI capital demand | B38: Higher | C38: A capex boom pushes investment demand out against a fixed pool of savings, raising the equilibrium real rate. Increasingly debt-financed, which adds directly to the supply of duration.
A39: Fiscal supply | B39: Higher | C39: Federal deficits near 6% of GDP require sustained Treasury issuance, absorbed by price-sensitive rather than official buyers.
A40: Balance sheet reduction | B40: Higher | C40: The Federal Reserve is no longer absorbing duration; quantitative easing suppressed the term premium for roughly a decade.
A41: Foreign official demand | B41: Higher | C41: Reduced reserve accumulation removes a price-insensitive source of demand.
A42: Inflation uncertainty | B42: Higher | C42: Persistent inflation raises the compensation demanded for the risk of an upside surprise.
A44: The observed term premium of 0.72% is far below its pre-2008 average, which routinely topped 1.5%. The forecast assumes
A45: only partial normalization. This is where the AI thesis enters the rate forecast - through capital demand and the supply
A46: of duration, not through faster growth. So the forecast holds even if growth disappoints.
A48: Cross-check — Growth Anchor
...

Sheet Period Alignment
A1: Period Alignment
A2: Reconciling this model's forecast horizon with published calendar-year projections.
A4: This model forecasts twelve months forward from the build date. The Federal Reserve and forecaster surveys publish on a
A5: fourth-quarter-over-fourth-quarter calendar-year basis. The two are not directly comparable: by mid-2026 the calendar
A6: 2026 projection is mostly realized history, while this model covers the second half of 2026 and the first half of 2027.
A7: Comparing them without adjusting overstates or understates the gap, depending on which way the projected path runs.
A9: Aligning the horizons
A10: Measure | B10: Calendar 2026 (Q4/Q4) | C10: Calendar 2027 (Q4/Q4) | D10: Implied mid-2026 to mid-2027 | E10: Source
A11: FOMC SEP — PCE inflation | B11: 3.6% | C11: 2.3% | D11: ~2.95% | E11: Summary of Economic Projections, June 17, 2026
A12: Converted to a CPI basis (+0.35pp) | B12: ~3.95% | C12: ~2.65% | D12: ~3.30% | E12: CPI has historically exceeded PCE by roughly a third of a point
A13: Philadelphia Fed SPF — headline CPI | B13: 3.5% | C13: 2.5% | D13: ~3.00% | E13: Q2 2026 survey, 33 forecasters
A14: FOMC SEP — real GDP | B14: 2.2% | C14: 2.3% | D14: ~2.25% | E14: Summary of Economic Projections, June 17, 2026
A15: FOMC SEP — federal funds rate | B15: 3.8% | C15: 3.6% | D15: ~3.70% | E15: Year-end median projections
A17: This model against the aligned benchmarks
A18: Measure | B18: ACCM forecast | C18: Aligned benchmark | D18: Difference | E18: Assessment
A19: Inflation (CPI basis) | B19: =TEXT(SUMMARY!B15,"0.0%") -> 3.4% | C19: ~3.0% to 3.3% | D19: Modestly above | E19: Consistent with the inflation-persistence thesis
A20: Real GDP growth | B20: ~1.8 to 2.2% | C20: ~2.25% | D20: Approximate | E20: Derived by deflating with a CPI-style build, not a GDP deflator. Not a thesis input.
A21: Ten-year Treasury | B21: =TEXT(SUMMARY!B21,"0.0%") -> 4.9% | C21: 4.78% prevailing | D21: Modestly above | E21: A forecast of further term premium normalization
A22: Unemployment rate | B22: =TEXT(SUMMARY!B23,"0.0%") -> 4.4% | C22: 4.3% | D22: Broadly in line | E22: FOMC projection for the fourth quarter of 2026
A24: Read: the model is slightly below official projections on real growth, in line on unemployment, and more hawkish on inflation and
A25: rates. That is the intended pattern. The portfolio thesis is a view on inflation persistence and the level of rates, not on the
A26: pace of real activity. A model that also diverged on growth would be making several bets at once instead of one.

Sheet Benchmarking
A1: Benchmarking
A2: Validation of the model output against professional forecasters, and identification of where the house view diverges.
A4: 2026 Forecast Comparison
A5: Source | B5: Real GDP | C5: Inflation | D5: Policy rate path | E5: Published
A6: ACCM (this model) | B6: =TEXT(SUMMARY!B16,"0.0%") -> 1.8% | C6: =TEXT(SUMMARY!B15,"0.0%")&" CPI" -> 3.4% CPI | D6: Elevated; ten-year forecast 4.90% | E6: July 2026
A7: FOMC Summary of Economic Projections | B7: 2.2% | C7: 3.6% PCE / 3.3% core PCE | D7: 3.8% (2026), 3.6% (2027), 3.4% (2028), 3.1% longer run | E7: June 17, 2026
A8: Philadelphia Fed Survey of Professional Forecasters | B8: 2.2% | C8: 3.5% CPI, Q4 over Q4 | D8: Not published | E8: Q2 2026 survey, 33 forecasters
A9: Bloomberg economist consensus | B9: 2.1% | C9: 3.4% CPI | D9: Easing toward 3.5% | E9: July 2026
A10: J.P. Morgan Asset Management | B10: 1.8-2.0% | C10: CPI peaking near 3.5%, then easing | D10: Two cuts expected | E10: Mid-2026 outlook
A11: Market pricing (ACM decomposition) | B11: n/a | C11: n/a | D11: Average overnight rate of 4.06% over ten years | E11: July 23, 2026
A13: Growth. Real GDP is derived by deflating nominal growth with this model's CPI-style inflation build rather than a GDP deflator, so it
A14: is approximate. The house view rests on nominal growth, inflation persistence and the level of rates, not on a real growth call.
A15: Inflation. The comparison needs care. Published projections are fourth-quarter-over-fourth-quarter for a calendar year; this model forecasts twelve months forward. Aligned to mid-2026 through mid-2027, the FOMC path implies roughly 3.3% CPI and the SPF roughly 3.0%. This model sits modestly above both,
A16: consistent with the inflation-persistence thesis. Comparing directly against the calendar-2026 figure would be an error, since most of that year has already happened. See Period Alignment.
A17: Rates. The Committee raised its 2026 policy rate projection from 3.4% to 3.8% between March and June, after projecting cuts twice. Market pricing is more hawkish still - an average overnight rate of 4.06% over ten years against the 3.25% implied by the Committee path. ACCM is aligned with the market.
A18: AI Capital Expenditure — Filed Data and External Corroboration
A19: Source | B19: Figure | C19: Basis
A20: ACCM, from SEC filings | B20: 2025 actual $424.3B for the five hyperscalers, +74.4% year over year; Q1 2026 running +90.8% | C20: 10-K and 10-Q XBRL, accession numbers on the AI Capex Build sheet
A21: ACCM, adopted forward scenario | B21: $701.6B for 2026, the midpoint of a $593.5B floor and an $809.6B ceiling | C21: Both bounds derived from filed data; no reliance on guidance
A22: J.P. Morgan Global Research | B22: Hyperscaler capex $650B in 2026, above $1.1T in 2027; global AI capex $5.5T through 2030 | C22: Midyear outlook, June 24, 2026
A23: Sell-side consensus | B23: Roughly $697B for the five companies in 2026, raised by $173B since January | C23: Mid-2026
A24: J.P. Morgan Asset Management | B24: AI capex contributed 1.1% to GDP growth in the first half of 2025 | C24: On the Minds of Investors — see the reconciliation note below
A25: CreditSights | B25: Recurring hyperscaler capex estimate series | C25: 2026, updated periodically
A27: The adopted forward figure of $701.6B sits slightly above J.P. Morgan Global Research at $650B and sell-side consensus at $697B, and is
A28: $697B, and is derived independently of both - from filed capex rather than guidance or analyst aggregation. Three
A29: sources using different methods landing within about 8% of each other is meaningful support.
A31: Reconciling the J.P. Morgan Asset Management figure. Their 1.1% contribution to GDP growth and this model's roughly 0.6 point are not in
A32: conflict - they measure different things. J.P. Morgan covers all AI-related investment across the economy (data centres, power,
A33: semiconductors, software) for the first half of 2025. This model covers only the incremental US capex of five named companies over twelve
A34: months forward. The narrower definition gives the smaller number, and the gap is about the size the difference in scope would predict.
A36: Reference Sources
A37: Publication | B37: Access and frequency
A38: Philadelphia Fed, Survey of Professional Forecasters | B38: philadelphiafed.org — quarterly, February, May, August, November
A39: Federal Reserve, Summary of Economic Projections | B39: federalreserve.gov — March, June, September, December meetings
A40: Federal Reserve Bank of New York, ACM term premium estimates | B40: newyorkfed.org — daily; used for the interest rate decomposition
A41: Congressional Budget Office, Budget and Economic Outlook | B41: cbo.gov — two to three updates per year
A42: Bureau of Economic Analysis, National Income and Product Accounts | B42: bea.gov via fred.stlouisfed.org — quarterly
A43: Bureau of Labor Statistics, Employment Situation | B43: bls.gov — monthly, first Friday
A44: Federal Reserve Bank of Atlanta, Wage Growth Tracker | B44: atlantafed.org — monthly
A45: SEC EDGAR XBRL company-concept API | B45: data.sec.gov — capital expenditure as filed; updated each 10-Q and 10-K

Sheet Commodity Refresh
A1: Commodity Basket Refresh
A2: Comparison of the materials basket at the model build date and at July 25, 2026, with a diagnostic on which reading to adopt.
A4: Basket comparison
A5: Commodity | B5: Weight | C5: Build: spot | D5: Build: 1yr fwd | E5: Build: change | F5: Current: spot | G5: Current: 1yr fwd | H5: Current: change
A6: WTI Crude | B6: 0.3 | C6: 68.78 | D6: 67.92 | E6: -0.0063 | F6: 83.96 | G6: 70.81 | H6: -0.0816
A7: Soybeans | B7: 0.1 | C7: 1122.75 | D7: 1175.75 | E7: 0.0472 | F7: 1188.5 | G7: 1218.75 | H7: 0.0255
A8: Corn | B8: 0.1 | C8: 417.5 | D8: 494.25 | E8: 0.1838 | F8: 468.5 | G8: 497.75 | H8: 0.0624
A9: Copper | B9: 0.15 | C9: 6.2275 | D9: 6.4665 | E9: 0.0384 | F9: 6.5 | G9: 6.62 | H9: 0.0185
A10: Gold | B10: 0.2 | C10: 4110.2 | D10: 4265 | E10: 0.0377 | F10: 4162.8 | G10: 4283.4 | H10: 0.029
A11: Sugar | B11: 0.05 | C11: 13.92 | D11: 15.07 | E11: 0.0826 | F11: 14.44 | G11: 15.17 | H11: 0.0506
A12: Coffee | B12: 0.05 | C12: 2.484 | D12: 2.3545 | E12: -0.0521 | F12: 324.5 | G12: 297.75 | H12: -0.0824
A13: Live Cattle | B13: 0.05 | C13: 241.775 | D13: 225.975 | E13: -0.0654 | F13: 227.45 | G13: 213.9 | H13: -0.0596
A14: Weighted net materials inflation | E14: =SUMPRODUCT(B6:B13,E6:E13) -> 0.032765 | H14: =SUMPRODUCT(B6:B13,H6:H13) -> -0.011685
A15: Coffee is quoted in dollars per pound at the build date and cents per pound in the refreshed pull. The percentage change is unaffected,
A16: since both halves of each ratio use the same units. Prices retrieved July 25, 2026 from exchange futures (CME, CBOT, COMEX, ICE) via Yahoo
A17: Finance. The deferred contract is the July 2027 expiry, or the nearest listed month where July is not traded.
A19: Resulting inflation forecast
A20: Vintage | B20: Labor (68%) | C20: Materials (32%) | D20: Blended forecast
A21: Model build date | B21: 0.035 | C21: =E14 -> 0.032765 | D21: =0.68*B21+0.32*C21 -> 0.0342848
A22: Refreshed, July 25, 2026 | B22: 0.035 | C22: =H14 -> -0.011685 | D22: =0.68*B22+0.32*C22 -> 0.0200608
A24: Diagnostic — why the refreshed reading is not adopted
A25: Test | B25: Finding
A26: What drove the change | B26: Mostly crude, but not only. Of the 4.45 point fall, crude is 2.26 points (51%) as its curve moved from flat into steep backwardation - spot $83.96 against July 2027 at $70.81. Corn is another 1.21 points (27%) as its forward premium collapsed from +18.4% to +6.2%. The other six share the remaining 22%.
A27: Is the spot price representative | B27: No. Spot is elevated by a geopolitical supply disruption. Using an event-inflated spot as the denominator manufactures a forecast of falling prices - the same distortion corrected in the investment and trade series, and fixable the same way.
A28: Are futures curves reliable predictors | B28: Only partly. A futures curve prices storage costs, convenience yield and risk premia as well as expectations. Backwardation in crude usually signals tightness now, not cheaper oil later.
A29: Internal consistency check | B29: Decisive. Nominal GDP of 5.25% less 2.0% inflation implies real growth of 3.2%, against consensus near 2.2%. Hold nominal GDP and consensus real growth, and the implied inflation rate is about 3.0%.
A30: Coverage limitation | B30: The basket measures producer input costs. CPI is about two-thirds services, and shelter alone is roughly a third of the index and its stickiest part. A commodity-weighted basket understates inflation when goods fall while services do not.
A32: Conclusion
A33: The model keeps the build-date inflation forecast. The refreshed basket is shown here as a disclosed sensitivity, not adopted, for two reasons. Crude is the largest single contributor to the move, at about half of it, and its spot price is event-distorted. The resulting
A34: from an event-distorted crude spot price, and the resulting forecast fails the consistency check against consensus real growth.
A35: The refreshed reading does carry a real signal, and one the Fed shares: energy normalization pulls headline inflation lower through 2027, which is exactly the FOMC path from 3.6%
A36: PCE in 2026 to 2.3% in 2027.
A37: The portfolio thesis does not rest on this. The rate forecast is built from the market-implied policy path and the term premium, neither of which uses the commodity basket.

Sheet Limitations
A1: Limitations and Known Sensitivities
A2: Disclosed weaknesses, their direction, and their magnitude. Stated before they are asked about.
A4: Every forecast rests on assumptions that may be wrong. What separates professional work from amateur work is
A5: not the absence of weakness but whether it is identified, sized and disclosed. This is the full list for this
A6: model.
A8: Structural limitations
A9: Limitation | B9: Effect | C9: Magnitude
A10: The inflation model has no shelter component | B10: The build weights labor 68% and materials 32% - production-cost weights. CPI is about two-thirds services, and shelter alone is roughly a third of the index and its stickiest part. The model will understate inflation whenever services run hot while goods fall, which is the current regime. | C10: Material. The single largest structural weakness. The fix is a rebuild at BLS relative-importance weights, identified as future work.
A11: Crude oil is over-weighted relative to CPI | B11: Crude carries 30% of the materials basket and therefore 9.6% of the inflation forecast, against roughly 6.2% for energy in the actual CPI basket. | C11: Moderate. Roughly three points of excess weight, which amplifies the forecast's sensitivity to energy shocks.
A12: Futures curves are imperfect predictors of spot prices | B12: A futures curve prices storage costs, convenience yield and risk premia alongside expectations. Backwardation in crude usually signals tightness now, not cheaper oil later. | C12: Moderate. Documented in the Commodity Refresh sheet, where a raw refresh of the basket is shown and rejected on these grounds.
A13: Five companies are an unrepresentative sample of national investment | B13: The bottom-up capital expenditure build covers firms accounting for under eight percent of gross private domestic investment. | C13: Contained by design. The build is a cross-check, not an input. The sensitivity on the AI Capex Build sheet shows that adopting it outright across the full capex range moves nominal GDP within a 47 basis point band, with the midpoint 8 basis points from the forecast.
A15: Unsupported assumptions
A16: Assumption | B16: Value | C16: Basis and sensitivity
A17: Share of hyperscaler capital expenditure located in the United States | B17: 65% | C17: Not disclosed in usable form. Companies report long-lived assets by geography under ASC 280-10-50-41, but as a balance-sheet stock rather than a flow, and segment boundaries differ. Sensitivity: each ten-point change moves the bottom-up estimate about 0.5 points and nominal GDP under 5 basis points - on a cross-check that is not adopted.
A18: Non-AI investment growth | B18: 1.5% | C18: Judgment: rate-sensitive equipment, structures and housing grow slowly with the ten-year near 4.5%. Applies only within the bottom-up cross-check.
A19: Equal weighting of trailing-year and current-year growth measures | B19: 50 / 50 | C19: Judgment: balances a stable measure against a current one. A 70/30 tilt toward the current measure would raise investment growth about 0.9 points and nominal GDP about 16 basis points.
A20: Term premium forecast | B20: 0.85% | C20: Observed ACM term premium of 0.72% plus 13 basis points of assumed further normalization. A disclosed active view, not a plug: anchored to a published, measured quantity, with five stated drivers.
A21: Expected average policy rate | B21: 4.05% | C21: Set at the market-implied level of 4.06% from the ACM decomposition. The model takes market pricing over the FOMC projection of 3.25%.
A22: Absorption rate of new labor force entrants | B22: 73% | C22: Judgment within the Consumer Build.
A31: Concentration risk
A32: Five companies deploy roughly 5% of all US private investment once their 65% domestic share is applied. Their combined capex grew 74% in 2025,
A33: with the latest quarter running 91% above a year earlier. The portfolio's Industrials and Energy overweights
A34: are directly levered to that spending. A material cut by any one of them would hit those sectors fast and
A35: would not show in the national accounts for at least a quarter. This is an identified, unhedged risk.
A38: What this model does not attempt
A39: Excluded | B39: Reason
A40: Recession probability | B40: The model forecasts a central path, not a distribution. It contains no mechanism for regime change.
A41: Quarterly path | B41: All outputs are twelve-month forward averages. The model says nothing about sequencing within the year.
A42: Policy reaction function | B42: The Fed path is taken from market pricing rather than modeled as a response to the model's own inflation and unemployment forecasts. That makes the rate forecast partly exogenous.
A43: Exchange rates and international spillovers | B43: Net trade is forecast from its own trend, without a currency or foreign demand channel.

Sheet Sheet1
