Workbook

Sheet DGM - JPM
A1: JPMorgan Chase & Co. (NYSE: JPM)
A2: Dividend Growth Model on total shareholder payout
A3: Angel City Capital Management | Andrew Pasten | Valuation date June 1, 2026 | Frozen July 31, 2026
A5: SHAREHOLDER PAYOUT HISTORY ($ millions)
A6: Item | B6: FY2021 | C6: FY2022 | D6: FY2023 | E6: FY2024 | F6: FY2025 | G6: Source
A7: Dividends paid | B7: 12858 | C7: 13562 | D7: 13463 | E7: 14783 | F7: 16625 | G7: JPM cash flow statement via Bloomberg
A8: Stock repurchased | B8: 20983 | C8: 10596 | D8: 9824 | E8: 28680 | F8: 34591 | G8: JPM cash flow statement via Bloomberg
A9: Stock issued (negative) | B9: -7350 | C9: 0 | D9: 0 | E9: -2500 | F9: -3000 | G9: JPM cash flow statement via Bloomberg
A10: Net cash to shareholders | B10: =SUM(B7:B9) -> 26491 | C10: =SUM(C7:C9) -> 24158 | D10: =SUM(D7:D9) -> 23287 | E10: =SUM(E7:E9) -> 40963 | F10: =SUM(F7:F9) -> 48216
A11: Operating net income | B11: 46839.54 | C11: 36762.58 | D11: 49087.2 | E11: 57645.36 | F11: 56015.96 | G11: Bloomberg, operating basis not GAAP
A12: Payout ratio | B12: =B10/B11 -> 0.56556918 | C12: =C10/C11 -> 0.6571356 | D12: =D10/D11 -> 0.47440066 | E12: =E10/E11 -> 0.71060359 | F12: =F10/F11 -> 0.86075468
A13: Diluted shares (millions) | B13: 3026.6 | C13: 2970 | D13: 2943.1 | E13: 2879 | F13: 2781.5 | G13: JPM Form 10-K
A15: MODEL INPUTS
A16: Input | B16: Value | C16: Source
A17: Average payout ratio, FY2021-25 | B17: =AVERAGE(B12:F12) -> 0.65369274 | C17: Five-year mean (1)
A18: Retention ratio | B18: =1-B17 -> 0.34630726
A19: Risk-free rate (10-yr Treasury) | B19: 0.0445 | C19: Market, 1 Jun 2026
A20: Beta (adjusted) | B20: 0.988 | C20: Bloomberg, May 2026
A21: Equity risk premium | B21: 0.0448 | C21: Damodaran implied ERP, May 2026 (2)
A22: FY2026 operating net income ($M) | B22: 60485.54 | C22: Bloomberg consensus at initiation
A23: Return on equity | B23: 0.17 | C23: JPM reported, FY2025
A25: COST OF EQUITY AND GROWTH
A26: Item | B26: Value | C26: Source
A27: Cost of equity (CAPM) | B27: =B19+B20*B21 -> 0.0887624 | C27: rf + beta x ERP
A28: Growth rate (g) | B28: 0.0445 | C28: Set to the 10-yr Treasury (3)
A29: Capitalization spread (Ke - g) | B29: =B27-B28 -> 0.0442624 | C29: (4)
A30: Check: beta x ERP | B30: =B20*B21 -> 0.0442624 | C30: Identical to the spread above
A31: Sustainable growth (ROE x retention) | B31: =B23*B18 -> 0.058872234 | C31: Cross-check (5)
A34: VALUATION
A35: Item | B35: Value | C35: Source
A36: Net cash to shareholders, FY2026E ($M) | B36: =B22*B17 -> 39538.959
A37: Shareholder cash flow per share | B37: =B36/F13 -> 14.214977 | C37: FY2025 diluted share count
A38: Intrinsic value per share at January 1, 2026 | B38: =B37/B29 -> 321.15242 | C38: Capitalised at the spread
A39: Months from that date to the target date of June 1, 2027 | B39: 17 | C39: Seventeen months. The FY2026 cash flow dates the value at January 1, 2026.
A40: TWELVE-MONTH TARGET PRICE (June 1, 2027) | B40: =B38*(1+B28)^(B39/12) -> 341.58451 | C40: Accreted at g, not at the cost of equity. Price grows at g. The gap between g and Ke is the dividend.
A42: EXPECTED RETURN
A43: Item | B43: Value | C43: Source
A44: Purchase price | B44: 299.31 | C44: May 29, 2026 close
A45: Price appreciation | B45: =B40/B44-1 -> 0.14123988
A46: Dividend yield at purchase | B46: =F7/F13/B44 -> 0.019969232 | C46: FY2025 dividends per share
...

Sheet Scenarios & Sensitivity
A1: Scenarios and Sensitivity
A2: JPMorgan Chase - Dividend Growth Model
A4: SCENARIOS
A5: Scenario | B5: Net income ($M) | C5: Payout | D5: Cash/share | E5: Value start FY26 | F5: Target | G5: vs. purchase
A6: Bear - credit overshoot | B6: ='DGM - JPM'!$B$22*0.87 -> 52622.42 | C6: 0.55 | D6: =B6*C6/'DGM - JPM'!$F$13 -> 10.405296 | E6: =D6/'DGM - JPM'!$B$29 -> 235.08206 | F6: =E6*(1+'DGM - JPM'!$B$28)^('DGM - JPM'!$B$39/12) -> 250.03825 | G6: =F6/'DGM - JPM'!$B$44-1 -> -0.1646178
A7: Base - consensus, 5-yr avg payout | B7: ='DGM - JPM'!$B$22 -> 60485.54 | C7: ='DGM - JPM'!B17 -> 0.65369274 | D7: =B7*C7/'DGM - JPM'!$F$13 -> 14.214977 | E7: =D7/'DGM - JPM'!$B$29 -> 321.15242 | F7: =E7*(1+'DGM - JPM'!$B$28)^('DGM - JPM'!$B$39/12) -> 341.58451 | G7: =F7/'DGM - JPM'!$B$44-1 -> 0.14123988
A8: Bull - capital return accelerates | B8: ='DGM - JPM'!$B$22 -> 60485.54 | C8: 0.73 | D8: =B8*C8/'DGM - JPM'!$F$13 -> 15.874328 | E8: =D8/'DGM - JPM'!$B$29 -> 358.64138 | F8: =E8*(1+'DGM - JPM'!$B$28)^('DGM - JPM'!$B$39/12) -> 381.45856 | G8: =F8/'DGM - JPM'!$B$44-1 -> 0.27445978
A10: (1) Earnings and payout vary. Cost of equity and growth are held constant, so the range isolates fundamental risk rather than
A11: discount-rate risk. The bear payout of 55% is what JPM actually distributed in 2022-23 under tighter capital requirements; the bull 73% is what it ran
A12: across 2024-25. Base case ruled.
A14: SENSITIVITY - target price ($ per share)
A15: Ke \ g | B15: 0.0395 | C15: 0.042 | D15: 0.0445 | E15: 0.047 | F15: 0.0495
A16: 0.0838 | B16: ='DGM - JPM'!$B$37/($A16-0.0395)*(1+0.0395)^('DGM - JPM'!$B$39/12) -> 338.98239 | C16: ='DGM - JPM'!$B$37/($A16-0.042)*(1+0.042)^('DGM - JPM'!$B$39/12) -> 360.48108 | D16: ='DGM - JPM'!$B$37/($A16-0.0445)*(1+0.0445)^('DGM - JPM'!$B$39/12) -> 384.71629 | E16: ='DGM - JPM'!$B$37/($A16-0.047)*(1+0.047)^('DGM - JPM'!$B$39/12) -> 412.24571 | F16: ='DGM - JPM'!$B$37/($A16-0.0495)*(1+0.0495)^('DGM - JPM'!$B$39/12) -> 443.78965
A17: 0.0863 | B17: ='DGM - JPM'!$B$37/($A17-0.0395)*(1+0.0395)^('DGM - JPM'!$B$39/12) -> 320.87435 | C17: ='DGM - JPM'!$B$37/($A17-0.042)*(1+0.042)^('DGM - JPM'!$B$39/12) -> 340.13791 | D17: ='DGM - JPM'!$B$37/($A17-0.0445)*(1+0.0445)^('DGM - JPM'!$B$39/12) -> 361.70694 | E17: ='DGM - JPM'!$B$37/($A17-0.047)*(1+0.047)^('DGM - JPM'!$B$39/12) -> 386.02143 | F17: ='DGM - JPM'!$B$37/($A17-0.0495)*(1+0.0495)^('DGM - JPM'!$B$39/12) -> 413.6409
A18: 0.0888 | B18: ='DGM - JPM'!$B$37/($A18-0.0395)*(1+0.0395)^('DGM - JPM'!$B$39/12) -> 304.60284 | C18: ='DGM - JPM'!$B$37/($A18-0.042)*(1+0.042)^('DGM - JPM'!$B$39/12) -> 321.96815 | D18: ='DGM - JPM'!$B$37/($A18-0.0445)*(1+0.0445)^('DGM - JPM'!$B$39/12) -> 341.29458 | E18: ='DGM - JPM'!$B$37/($A18-0.047)*(1+0.047)^('DGM - JPM'!$B$39/12) -> 362.93402 | F18: ='DGM - JPM'!$B$37/($A18-0.0495)*(1+0.0495)^('DGM - JPM'!$B$39/12) -> 387.32786
A19: 0.0913 | B19: ='DGM - JPM'!$B$37/($A19-0.0395)*(1+0.0395)^('DGM - JPM'!$B$39/12) -> 289.90193 | C19: ='DGM - JPM'!$B$37/($A19-0.042)*(1+0.042)^('DGM - JPM'!$B$39/12) -> 305.64116 | D19: ='DGM - JPM'!$B$37/($A19-0.0445)*(1+0.0445)^('DGM - JPM'!$B$39/12) -> 323.06304 | E19: ='DGM - JPM'!$B$37/($A19-0.047)*(1+0.047)^('DGM - JPM'!$B$39/12) -> 342.45242 | F19: ='DGM - JPM'!$B$37/($A19-0.0495)*(1+0.0495)^('DGM - JPM'!$B$39/12) -> 364.16232
A20: 0.0938 | B20: ='DGM - JPM'!$B$37/($A20-0.0395)*(1+0.0395)^('DGM - JPM'!$B$39/12) -> 276.55469 | C20: ='DGM - JPM'!$B$37/($A20-0.042)*(1+0.042)^('DGM - JPM'!$B$39/12) -> 290.89014 | D20: ='DGM - JPM'!$B$37/($A20-0.0445)*(1+0.0445)^('DGM - JPM'!$B$39/12) -> 306.68053 | E20: ='DGM - JPM'!$B$37/($A20-0.047)*(1+0.047)^('DGM - JPM'!$B$39/12) -> 324.15902 | F20: ='DGM - JPM'!$B$37/($A20-0.0495)*(1+0.0495)^('DGM - JPM'!$B$39/12) -> 343.6114
A22: (2) Base case boxed. Value depends far more on the spread between Ke and g than on the level of either, which is the characteristic
A23: constant-growth model. Narrowing the 4.43 point spread by half a point raises the target roughly twelve percent. This is the largest single source of
A24: model risk.

Sheet Method, Sources & Limitations
A1: Method, Sources and Limitations
A2: JPMorgan Chase - Dividend Growth Model
A4: Why total payout rather than dividends alone
A5: JPMorgan returned $48.2 billion to shareholders in FY2025, of which $16.6 billion was dividends and $31.6 billion net repurchase. A dividend-only
A6: model would capture roughly a third of the cash actually returned and would materially undervalue the company. The payout ratio is volatile year to
A7: year because buyback is discretionary and capital-regulation dependent, which is why a five-year average is used rather than the latest year - FY2025
A8: alone implies an 86% payout, well above what is sustainable through a credit cycle.
A10: Why the growth rate is set to the risk-free rate
A11: A mature, diversified bank of systemic scale cannot durably outgrow the nominal economy it lends into: loan demand, deposit balances, card volumes and
A12: payment flows all scale with nominal activity. The standard proxy for long-run nominal growth in a valuation context is the long bond yield. The
A13: sustainable growth identity provides the cross-check: g = ROE x retention = 17% x 34.6% = 5.9%, close to nominal GDP growth, which is exactly the
A14: premise the valuation rests on. Retained capital is not idle - it funds loan growth, absorbs the capital requirement that comes with a larger balance
... A24: DATA
A25: Input | B25: Source / date
A26: Share price at purchase $299.31 | B26: Market close, May 29, 2026
A27: Equity risk premium 4.48% | B27: Damodaran implied ERP, May 2026
A28: Beta (adjusted) 0.988 | B28: Bloomberg, May 2026
A29: Ten-year Treasury 4.45% | B29: Market level, June 1, 2026
A30: FY2026 operating net income $60,485.5M | B30: Bloomberg consensus at initiation
A31: Diluted shares 2,781.5M | B31: JPM Form 10-K, FY2025
A32: Payout history FY2021-FY2025 | B32: JPM cash flow statements via Bloomberg
A33: Return on equity 17% | B33: JPM reported, FY2025
A34: Analyst consensus 4.1/5, $348 target | B34: Bloomberg ANR, 38 analysts, July 6, 2026
A35: Capital return announcement $50B buyback | B35: JPM release following CCAR, June 24, 2026
A37: KEY ASSUMPTIONS AND SENSITIVITIES
A39: Sensitivity to the capitalization spread
A40: Value is a function of one over (Ke - g). At a 4.43 point spread, a half-point narrowing raises the target roughly twelve percent. Small
A41: changes in beta or the ERP transmit directly. Largest single source of model risk.
A42: The payout ratio is discretionary
A43: Buyback is the swing component, set by capital requirements and management judgment rather than by rule. The five-year average spans both
A44: the 2022-23 tightening and the 2024-25 acceleration.
A45: Earnings are consensus, not modeled
A46: FY2026 net income is taken from Bloomberg consensus rather than built from an NII and fee forecast, so the valuation inherits any bias in
A47: the Street estimate.
A49: RISKS TO THE THESIS
A50: Credit normalization overshooting
... A61: CELL CONVENTIONS
A62: Blue font | B62: Hard input - a data point or stated assumption
A63: Black font | B63: Formula calculated on this sheet
A64: Green font | B64: Link to another sheet in this workbook
...
